Ready
Status code Unknown from http://ipinfo.io/json: ERROR - HTTPConnectionPool(host='ipinfo.io', port=80): Max retries exceeded with url: /json (Caused by NewConnectionError('<urllib3.connection.HTTPConnection object at 0x735c37f0>: Failed to establish a new connection: [Errno -2] Name or service not known',))
send location
37.386 -122.084
send location
37.386 -122.084
send location
37.386 -122.084
send location
37.386 -122.084
send location
Process Process-1:
Traceback (most recent call last):
  File "/usr/lib/python3.4/multiprocessing/process.py", line 254, in _bootstrap
    self.run()
  File "/usr/lib/python3.4/multiprocessing/process.py", line 93, in run
    self._target(*self._args, **self._kwargs)
  File "main.py", line 35, in coordThread
    latitude, longitude = geocoder.ip("me").latlng
TypeError: 'NoneType' object is not iterable
